Workbook
Name JR_PAGE_ANCHOR_0_1: 'Rincian Faktur Penjualan'!$A$1

Sheet Potongan Teknisi MF
A3: DAFTAR POTONGAN GAJI KARYAWAN MADINAH FLASH CIBUBUR
B5: HASIL AUDIT BULAN JULI 2026
B6: MINUS AUDIT ALL STOCK | C6: 0
B7: MINUS AUDIT SAMPEL STOCK | C7: 0
D8: =C6+C7 -> 0
B9: PLUS AUDIT ALL STOCK | C9: 0
B10: PLUS AUDIT SAMPEL STOCK | C10: 0
D11: =C9+C10 -> 0
B12: TOTAL SALES BULAN JULI 2026 | C12: 20732243
B13: BUDGET STORE MF 0.15% | C13: =C12*0.15% -> 31098.364
B14: TOTAL NKL ( NILAI YANG HARUS DI BAYAR) | C14: =D8-D11-C13 -> -31098.364
B15: TOTAL NILAI POTONGAN TIM TEKNISI MF (50%) | C15: =C14*50/100 -> -15549.182
B16: NILAI YANG SUDAH DIBAYAR MFLASH WARBONG | C16: 0
B17: SISA BEBAN YANG HARUS DIBAYAR MFLASH CIBUBUR | C17: =C15-C16 -> -15549.182
B18: NAMA PERSONIL TOKO | C18: JABATAN | D18: PROKSI POTONGAN | E18: TOTAL POTONGAN | F18: POTONGAN PER BULAN | G18: AGUSTUS | H18: KETERANGAN
B19: Belum ada Absensi Teknisi | C19: Teknisi | D19: 1 | E19: =C17/D23 -> -3887.2956 | F19: =E19/1 -> -3887.2956 | G19: =F$19*D19 -> -3887.2956 | H19: TIDAK DIPOTONG BARU BUKA 31/07/2026
B20: Belum ada Absensi Teknisi | C20: Teknisi | D20: 1 | G20: =F$19*D20 -> -3887.2956 | H20: TIDAK DIPOTONG BARU BUKA 31/07/2026
B21: Belum ada Absensi Teknisi | C21: Teknisi | D21: 1 | G21: =F$19*D21 -> -3887.2956 | H21: TIDAK DIPOTONG BARU BUKA 31/07/2026
B22: Belum ada Absensi Teknisi | C22: Teknisi | D22: 1 | G22: =F$19*D22 -> -3887.2956 | H22: TIDAK DIPOTONG BARU BUKA 31/07/2026
B23: Total | D23: =SUM(D19:D22) -> 4 | G23: =SUM(G19:G22) -> -15549.182 | H23: =SUM(G23:G23) -> -15549.182

Sheet Rincian Faktur Penjualan
B1: TGL FAKTUR | C1: i | D1: NO FAKTUR | E1: i | F1: Nomor # Pengiriman Pesanan | G1: i | H1: Tanggal Pengiriman Pesanan | I1: i | J1: KATEGORI PELANGGAN | K1: i | L1: ID PELANGGAN | M1: i | N1: NAMA CUSTOMER | O1: i | P1: NAMA ADMIN | Q1: i | R1: KATEGORI PENJUALAN | S1: i | T1: KATEGORI BARANG | U1: i | V1: NAMA TEKNISI | W1: i | X1: NAMA TEKNISI (FINAL) | Y1: i | Z1: YANG MENYERAHKAN/MENJUAL | AA1: i | AB1: KERUSAKAN UTAMA | AC1: i | AD1: MERK UNIT | AE1: i | AF1: TIPE UNIT | AG1: i | AH1: KODE BARANG | AI1: i | AJ1: NAMA BARANG | AK1: i | AL1: HARGA BELI | AM1: i | AN1: QTY | AO1: i | AP1: @HARGA | AQ1: i | AR1: TOTAL HARGA | AS1: i | AT1: Nama Default Penjual Pelanggan Faktur Penjualan | AU1: Kata Kunci
B2: 46234 | D2: MF-FP.0001 | F2: DO.2026.07.00008 | H2: 46234 | J2: MEMBER REGULER | L2: MR. 082211643104 | N2: CADLI | P2: RAYHAN KAFFI BUDIMAN | R2: SERVICE HP | T2: JASA | V2: IKANG TAUFIK | X2: IKANG TAUFIK | Z2: RAYHAN KAFFI BUDIMAN | AB2: LCD | AD2: XIAOMI | AF2: REDMI 8A | AH2: 100236 | AJ2: JS HP LCD - INTERFACE | AL2: 0 | AN2: 1 | AP2: 100000 | AR2: 100000 | AT2: SUPRIYADI | AU2: =_xlfn.IFS(ISNUMBER(SEARCH("Interface", AJ2)), "Omset Interface", ISNUMBER(SEARCH("Normal", AJ2)), "Omset Normal", ISNUMBER(SEARCH("Mati Total", AJ2)), "Omset Mati Total", ISNUMBER(SEARCH("Promo", AJ2)), "Omset Promo", TRUE, "Omset lainnya") -> Omset Interface
B3: 46234 | D3: MF-FP.0001 | F3: DO.2026.07.00008 | H3: 46234 | J3: MEMBER REGULER | L3: MR. 082211643104 | N3: CADLI | P3: RAYHAN KAFFI BUDIMAN | R3: SERVICE HP | T3: AKSESORIS | V3: IKANG TAUFIK | X3: IKANG TAUFIK | Z3: RAYHAN KAFFI BUDIMAN | AB3: LCD | AD3: XIAOMI | AF3: REDMI 8A | AH3: 100194 | AJ3: LUNA USB CABLE CB-2EC | AL3: 17450 | AN3: 1 | AP3: 20000 | AR3: 20000 | AT3: SUPRIYADI | AU3: =_xlfn.IFS(ISNUMBER(SEARCH("Interface", AJ3)), "Omset Interface", ISNUMBER(SEARCH("Normal", AJ3)), "Omset Normal", ISNUMBER(SEARCH("Mati Total", AJ3)), "Omset Mati Total", ISNUMBER(SEARCH("Promo", AJ3)), "Omset Promo", TRUE, "Omset lainnya") -> Omset lainnya
B4: 46234 | D4: MF-FP.0003 | F4: DO.2026.07.00015 | H4: 46234 | J4: MEMBER REGULER | L4: MR. 085717356063 | N4: MAT SANHI | P4: RAYHAN | R4: SERVICE HP | T4: JASA | V4: YUFI NOFERIANTO | X4: YUFI NOFERIANTO | Z4: RAYHAN | AB4: LCD | AD4: OPPO | AF4: A57 | AH4: 100236 | AJ4: JS HP LCD - INTERFACE | AL4: 0 | AN4: 1 | AP4: 100000 | AR4: 100000 | AU4: =_xlfn.IFS(ISNUMBER(SEARCH("Interface", AJ4)), "Omset Interface", ISNUMBER(SEARCH("Normal", AJ4)), "Omset Normal", ISNUMBER(SEARCH("Mati Total", AJ4)), "Omset Mati Total", ISNUMBER(SEARCH("Promo", AJ4)), "Omset Promo", TRUE, "Omset lainnya") -> Omset Interface
B5: 46234 | D5: MF-FP.0003 | F5: DO.2026.07.00015 | H5: 46234 | J5: MEMBER REGULER | L5: MR. 085717356063 | N5: MAT SANHI | P5: RAYHAN | R5: SERVICE HP | T5: AKSESORIS | V5: YUFI NOFERIANTO | X5: YUFI NOFERIANTO | Z5: RAYHAN | AB5: LCD | AD5: OPPO | AF5: A57 | AH5: 100194 | AJ5: LUNA USB CABLE CB-2EC | AL5: 17450 | AN5: 1 | AP5: 20000 | AR5: 20000 | AU5: =_xlfn.IFS(ISNUMBER(SEARCH("Interface", AJ5)), "Omset Interface", ISNUMBER(SEARCH("Normal", AJ5)), "Omset Normal", ISNUMBER(SEARCH("Mati Total", AJ5)), "Omset Mati Total", ISNUMBER(SEARCH("Promo", AJ5)), "Omset Promo", TRUE, "Omset lainnya") -> Omset lainnya
B6: 46234 | D6: MF-FP.0005 | F6: DO.2026.07.00021 | H6: 46234 | J6: Umum | L6: MR.081317813178 | N6: DANIS | P6: MUHAMMAD NUR HANIF | R6: SERVICE HP | T6: JASA | V6: YUFI NOFERIANTO | X6: YUFI NOFERIANTO | Z6: MUHAMMAD NUR HANIF | AB6: LCD | AD6: REALME | AF6: C63 | AH6: 100236 | AJ6: JS HP LCD - INTERFACE | AL6: 0 | AN6: 1 | AP6: 100000 | AR6: 100000 | AU6: =_xlfn.IFS(ISNUMBER(SEARCH("Interface", AJ6)), "Omset Interface", ISNUMBER(SEARCH("Normal", AJ6)), "Omset Normal", ISNUMBER(SEARCH("Mati Total", AJ6)), "Omset Mati Total", ISNUMBER(SEARCH("Promo", AJ6)), "Omset Promo", TRUE, "Omset lainnya") -> Omset Interface
B7: 46234 | D7: MF-FP.0005 | F7: DO.2026.07.00021 | H7: 46234 | J7: Umum | L7: MR.081317813178 | N7: DANIS | P7: MUHAMMAD NUR HANIF | R7: SERVICE HP | T7: AKSESORIS | V7: YUFI NOFERIANTO | X7: YUFI NOFERIANTO | Z7: MUHAMMAD NUR HANIF | AB7: LCD | AD7: REALME | AF7: C63 | AH7: 100194 | AJ7: LUNA USB CABLE CB-2EC | AL7: 17450 | AN7: 1 | AP7: 20000 | AR7: 20000 | AU7: =_xlfn.IFS(ISNUMBER(SEARCH("Interface", AJ7)), "Omset Interface", ISNUMBER(SEARCH("Normal", AJ7)), "Omset Normal", ISNUMBER(SEARCH("Mati Total", AJ7)), "Omset Mati Total", ISNUMBER(SEARCH("Promo", AJ7)), "Omset Promo", TRUE, "Omset lainnya") -> Omset lainnya
B8: 46234 | D8: MF-FP.0008 | F8: DO.2026.07.00022 | H8: 46234 | J8: MEMBER REGULER | L8: MR. 087870766210 | N8: RULI | P8: RAIHAN KAFFI BUDIMAN | R8: SERVICE HP | T8: JASA | V8: IKANG TAUFIK | X8: IKANG TAUFIK | Z8: RAIHAN KAFFI BUDIMAN | AB8: LCD | AD8: SAMSUNG | AF8: S20 ULTRA | AH8: 100236 | AJ8: JS HP LCD - INTERFACE | AL8: 0 | AN8: 1 | AP8: 180000 | AR8: 180000 | AU8: =_xlfn.IFS(ISNUMBER(SEARCH("Interface", AJ8)), "Omset Interface", ISNUMBER(SEARCH("Normal", AJ8)), "Omset Normal", ISNUMBER(SEARCH("Mati Total", AJ8)), "Omset Mati Total", ISNUMBER(SEARCH("Promo", AJ8)), "Omset Promo", TRUE, "Omset lainnya") -> Omset Interface
B9: 46234 | D9: MF-FP.0008 | F9: DO.2026.07.00022 | H9: 46234 | J9: MEMBER REGULER | L9: MR. 087870766210 | N9: RULI | P9: RAIHAN KAFFI BUDIMAN | R9: SERVICE HP | T9: AKSESORIS | V9: IKANG TAUFIK | X9: IKANG TAUFIK | Z9: RAIHAN KAFFI BUDIMAN | AB9: LCD | AD9: SAMSUNG | AF9: S20 ULTRA | AH9: 100194 | AJ9: LUNA USB CABLE CB-2EC | AL9: 17450 | AN9: 1 | AP9: 20000 | AR9: 20000 | AU9: =_xlfn.IFS(ISNUMBER(SEARCH("Interface", AJ9)), "Omset Interface", ISNUMBER(SEARCH("Normal", AJ9)), "Omset Normal", ISNUMBER(SEARCH("Mati Total", AJ9)), "Omset Mati Total", ISNUMBER(SEARCH("Promo", AJ9)), "Omset Promo", TRUE, "Omset lainnya") -> Omset lainnya
B10: 46234 | D10: MF-FP.0009 | F10: DO.2026.07.00023 | H10: 46234 | J10: Umum | L10: MR. 08118988023 | N10: UMAR | P10: MUHAMMAD NUR HANIF | R10: SERVICE HP | T10: JASA | V10: EGI SETYA RAMADANI | X10: EGI SETYA RAMADANI | Z10: MUHAMMAD NUR HANIF | AB10: LCD | AD10: SAMSUNG | AF10: A12 | AH10: 100236 | AJ10: JS HP LCD - INTERFACE | AL10: 0 | AN10: 1 | AP10: 100000 | AR10: 100000 | AU10: =_xlfn.IFS(ISNUMBER(SEARCH("Interface", AJ10)), "Omset Interface", ISNUMBER(SEARCH("Normal", AJ10)), "Omset Normal", ISNUMBER(SEARCH("Mati Total", AJ10)), "Omset Mati Total", ISNUMBER(SEARCH("Promo", AJ10)), "Omset Promo", TRUE, "Omset lainnya") -> Omset Interface
B11: 46234 | D11: MF-FP.0009 | F11: DO.2026.07.00023 | H11: 46234 | J11: Umum | L11: MR. 08118988023 | N11: UMAR | P11: MUHAMMAD NUR HANIF | R11: SERVICE HP | T11: AKSESORIS | V11: EGI SETYA RAMADANI | X11: EGI SETYA RAMADANI | Z11: MUHAMMAD NUR HANIF | AB11: LCD | AD11: SAMSUNG | AF11: A12 | AH11: 100194 | AJ11: LUNA USB CABLE CB-2EC | AL11: 17450 | AN11: 1 | AP11: 20000 | AR11: 20000 | AU11: =_xlfn.IFS(ISNUMBER(SEARCH("Interface", AJ11)), "Omset Interface", ISNUMBER(SEARCH("Normal", AJ11)), "Omset Normal", ISNUMBER(SEARCH("Mati Total", AJ11)), "Omset Mati Total", ISNUMBER(SEARCH("Promo", AJ11)), "Omset Promo", TRUE, "Omset lainnya") -> Omset lainnya
B12: 46234 | D12: MF-FP.0010 | F12: DO.2026.07.00024 | H12: 46234 | J12: Umum | L12: MR. 081906094845 | N12: AJI | P12: MUHAMMAD ANELKA | R12: SERVICE HP | T12: JASA | V12: YUFI NOFERIANTO | X12: YUFI NOFERIANTO | Z12: MUHAMMAD NUR HANIF | AB12: LCD | AD12: BELUM ADA MERK | AF12: TECNO CAMMON 40 | AH12: 100236 | AJ12: JS HP LCD - INTERFACE | AL12: 0 | AN12: 1 | AP12: 130000 | AR12: 130000 | AU12: =_xlfn.IFS(ISNUMBER(SEARCH("Interface", AJ12)), "Omset Interface", ISNUMBER(SEARCH("Normal", AJ12)), "Omset Normal", ISNUMBER(SEARCH("Mati Total", AJ12)), "Omset Mati Total", ISNUMBER(SEARCH("Promo", AJ12)), "Omset Promo", TRUE, "Omset lainnya") -> Omset Interface
B13: 46234 | D13: MF-FP.0010 | F13: DO.2026.07.00024 | H13: 46234 | J13: Umum | L13: MR. 081906094845 | N13: AJI | P13: MUHAMMAD ANELKA | R13: SERVICE HP | T13: AKSESORIS | V13: YUFI NOFERIANTO | X13: YUFI NOFERIANTO | Z13: MUHAMMAD NUR HANIF | AB13: LCD | AD13: BELUM ADA MERK | AF13: TECNO CAMMON 40 | AH13: 100194 | AJ13: LUNA USB CABLE CB-2EC | AL13: 17450 | AN13: 1 | AP13: 20000 | AR13: 20000 | AU13: =_xlfn.IFS(ISNUMBER(SEARCH("Interface", AJ13)), "Omset Interface", ISNUMBER(SEARCH("Normal", AJ13)), "Omset Normal", ISNUMBER(SEARCH("Mati Total", AJ13)), "Omset Mati Total", ISNUMBER(SEARCH("Promo", AJ13)), "Omset Promo", TRUE, "Omset lainnya") -> Omset lainnya
B14: 46234 | D14: MF-FP.0010 | F14: DO.2026.07.00024 | H14: 46234 | J14: Umum | L14: MR. 081906094845 | N14: AJI | P14: MUHAMMAD ANELKA | R14: SERVICE HP | T14: AKSESORIS | V14: YUFI NOFERIANTO | X14: YUFI NOFERIANTO | Z14: MUHAMMAD NUR HANIF | AB14: LCD | AD14: BELUM ADA MERK | AF14: TECNO CAMMON 40 | AH14: 100279 | AJ14: VIVAN HYDROGEL BASIC CRYSTAL CLEAR VSP01T | AL14: 20000 | AN14: 1 | AP14: 75000 | AR14: 75000 | AU14: =_xlfn.IFS(ISNUMBER(SEARCH("Interface", AJ14)), "Omset Interface", ISNUMBER(SEARCH("Normal", AJ14)), "Omset Normal", ISNUMBER(SEARCH("Mati Total", AJ14)), "Omset Mati Total", ISNUMBER(SEARCH("Promo", AJ14)), "Omset Promo", TRUE, "Omset lainnya") -> Omset lainnya
B15: 46234 | D15: MF-FP.0013 | F15: DO.2026.07.00028 | H15: 46234 | J15: Umum | L15: MR. 082260631634 | N15: GILANG | P15: MUHAMMAD NUR HANIF | R15: SERVICE HP | T15: JASA | V15: MUHAMMAD IBNU SIDDIQ | X15: MUHAMMAD IBNU SIDDIQ | Z15: MUHAMMAD NUR HANIF | AB15: LCD | AD15: APPLE | AF15: IPHONE 8 PLUS | AH15: 100236 | AJ15: JS HP LCD - INTERFACE | AL15: 0 | AN15: 1 | AP15: 100000 | AR15: 100000 | AU15: =_xlfn.IFS(ISNUMBER(SEARCH("Interface", AJ15)), "Omset Interface", ISNUMBER(SEARCH("Normal", AJ15)), "Omset Normal", ISNUMBER(SEARCH("Mati Total", AJ15)), "Omset Mati Total", ISNUMBER(SEARCH("Promo", AJ15)), "Omset Promo", TRUE, "Omset lainnya") -> Omset Interface
... B53: 46237 | D53: MF-FP.0036 | F53: DO.2026.08.00033 | H53: 46237 | J53: Umum | L53: MR. 081336557941 | N53: IBU HENI | P53: MUHAMMAD NUR HANIF | R53: SERVICE HP | T53: AKSESORIS | V53: FARID HASHBI SIDDIQ | X53: FARID HASHBI SIDDIQ | Z53: MUHAMMAD NUR HANIF | AB53: FLEXIBEL CHARGER (PAPAN KONEKTOR) | AD53: SAMSUNG | AF53: A50 | AH53: 100194 | AJ53: LUNA USB CABLE CB-2EC | AL53: 17450 | AN53: 1 | AP53: 20000 | AR53: 20000 | AU53: =_xlfn.IFS(ISNUMBER(SEARCH("Interface", AJ53)), "Omset Interface", ISNUMBER(SEARCH("Normal", AJ53)), "Omset Normal", ISNUMBER(SEARCH("Mati Total", AJ53)), "Omset Mati Total", ISNUMBER(SEARCH("Promo", AJ53)), "Omset Promo", TRUE, "Omset lainnya") -> Omset lainnya
B54: 46237 | D54: MF-FP.0040 | F54: DO.2026.08.00039 | H54: 46237 | J54: MEMBER REGULER | L54: MR. 082139720969 | N54: JESSY | P54: RAIHAN KAFFI BUDIMAN | R54: SERVICE HP | T54: JASA | V54: FARID HASHBI SIDDIQ | X54: FARID HASHBI SIDDIQ | Z54: RAIHAN KAFFI BUDIMAN | AB54: LCD | AD54: VIVO | AF54: Y12S | AH54: 100236 | AJ54: JS HP LCD - INTERFACE | AL54: 0 | AN54: 1 | AP54: 85000 | AR54: 85000 | AT54: RAIHAN KAFFI BUDIMAN | AU54: =_xlfn.IFS(ISNUMBER(SEARCH("Interface", AJ54)), "Omset Interface", ISNUMBER(SEARCH("Normal", AJ54)), "Omset Normal", ISNUMBER(SEARCH("Mati Total", AJ54)), "Omset Mati Total", ISNUMBER(SEARCH("Promo", AJ54)), "Omset Promo", TRUE, "Omset lainnya") -> Omset Interface
B55: 46237 | D55: MF-FP.0040 | F55: DO.2026.08.00039 | H55: 46237 | J55: MEMBER REGULER | L55: MR. 082139720969 | N55: JESSY | P55: RAIHAN KAFFI BUDIMAN | R55: SERVICE HP | T55: AKSESORIS | V55: FARID HASHBI SIDDIQ | X55: FARID HASHBI SIDDIQ | Z55: RAIHAN KAFFI BUDIMAN | AB55: LCD | AD55: VIVO | AF55: Y12S | AH55: 100278 | AJ55: VIVAN HYDROGEL BASIC ANTI GLARE VSP03T | AL55: 20000 | AN55: 1 | AP55: 35000 | AR55: 35000 | AT55: RAIHAN KAFFI BUDIMAN | AU55: =_xlfn.IFS(ISNUMBER(SEARCH("Interface", AJ55)), "Omset Interface", ISNUMBER(SEARCH("Normal", AJ55)), "Omset Normal", ISNUMBER(SEARCH("Mati Total", AJ55)), "Omset Mati Total", ISNUMBER(SEARCH("Promo", AJ55)), "Omset Promo", TRUE, "Omset lainnya") -> Omset lainnya
B56: 46237 | D56: MF-FP.0040 | F56: DO.2026.08.00039 | H56: 46237 | J56: MEMBER REGULER | L56: MR. 082139720969 | N56: JESSY | P56: RAIHAN KAFFI BUDIMAN | R56: SERVICE HP | T56: AKSESORIS | V56: FARID HASHBI SIDDIQ | X56: FARID HASHBI SIDDIQ | Z56: RAIHAN KAFFI BUDIMAN | AB56: LCD | AD56: VIVO | AF56: Y12S | AH56: 100194 | AJ56: LUNA USB CABLE CB-2EC | AL56: 17450 | AN56: 1 | AP56: 20000 | AR56: 20000 | AT56: RAIHAN KAFFI BUDIMAN | AU56: =_xlfn.IFS(ISNUMBER(SEARCH("Interface", AJ56)), "Omset Interface", ISNUMBER(SEARCH("Normal", AJ56)), "Omset Normal", ISNUMBER(SEARCH("Mati Total", AJ56)), "Omset Mati Total", ISNUMBER(SEARCH("Promo", AJ56)), "Omset Promo", TRUE, "Omset lainnya") -> Omset lainnya
B57: 46237 | D57: MF-FP.0047 | F57: DO.2026.08.00032 | H57: 46237 | J57: MEMBER REGULER | L57: MR. 085973985603 | N57: AKBAR | P57: MUHAMMAD ANELKA | R57: SERVICE HP | T57: JASA | V57: YUFI NOFERIANTO | X57: YUFI NOFERIANTO | Z57: MUHAMMAD NUR HANIF | AB57: LCD | AD57: XIAOMI | AF57: 11 T 5G | AH57: 100236 | AJ57: JS HP LCD - INTERFACE | AL57: 0 | AN57: 1 | AP57: 121000 | AR57: 121000 | AU57: =_xlfn.IFS(ISNUMBER(SEARCH("Interface", AJ57)), "Omset Interface", ISNUMBER(SEARCH("Normal", AJ57)), "Omset Normal", ISNUMBER(SEARCH("Mati Total", AJ57)), "Omset Mati Total", ISNUMBER(SEARCH("Promo", AJ57)), "Omset Promo", TRUE, "Omset lainnya") -> Omset Interface
B58: 46253 | D58: MF-FP.0195 | F58: DO.2026.08.00035 | H58: 46237 | J58: MEMBER REGULER | L58: MR. 081311002179 | N58: SAM | P58: RAIHAN KAFFI BUDIMAN | R58: SERVICE HP | T58: SPAREPART | V58: FARID HASHBI SIDDIQ | X58: FARID HASHBI SIDDIQ | Z58: RAIHAN KAFFI BUDIMAN | AB58: FLEXIBEL CHARGER (PAPAN KONEKTOR) | AD58: XIAOMI | AF58: REDMI NOTE 11 PRO 5G | AH58: 100363 | AJ58: BACKDOOR REDMI NOTE 11 PRO 5G BLACK | AL58: 88000 | AN58: 2 | AP58: 50000 | AR58: 100000 | AU58: =_xlfn.IFS(ISNUMBER(SEARCH("Interface", AJ58)), "Omset Interface", ISNUMBER(SEARCH("Normal", AJ58)), "Omset Normal", ISNUMBER(SEARCH("Mati Total", AJ58)), "Omset Mati Total", ISNUMBER(SEARCH("Promo", AJ58)), "Omset Promo", TRUE, "Omset lainnya") -> Omset lainnya
B59: 46253 | D59: MF-FP.0195 | F59: DO.2026.08.00035 | H59: 46237 | J59: MEMBER REGULER | L59: MR. 081311002179 | N59: SAM | P59: RAIHAN KAFFI BUDIMAN | R59: SERVICE HP | T59: SPAREPART | V59: FARID HASHBI SIDDIQ | X59: FARID HASHBI SIDDIQ | Z59: RAIHAN KAFFI BUDIMAN | AB59: FLEXIBEL CHARGER (PAPAN KONEKTOR) | AD59: XIAOMI | AF59: REDMI NOTE 11 PRO 5G | AH59: 100364 | AJ59: BAZEL REDMI NOTE 11 PRO 4G/5G | AL59: 40000 | AN59: 1 | AP59: 45000 | AR59: 45000 | AU59: =_xlfn.IFS(ISNUMBER(SEARCH("Interface", AJ59)), "Omset Interface", ISNUMBER(SEARCH("Normal", AJ59)), "Omset Normal", ISNUMBER(SEARCH("Mati Total", AJ59)), "Omset Mati Total", ISNUMBER(SEARCH("Promo", AJ59)), "Omset Promo", TRUE, "Omset lainnya") -> Omset lainnya
B60: 46237 | D60: MF-FP.0047 | F60: DO.2026.08.00032 | H60: 46237 | J60: MEMBER REGULER | L60: MR. 085973985603 | N60: AKBAR | P60: MUHAMMAD ANELKA | R60: SERVICE HP | T60: SPAREPART | V60: YUFI NOFERIANTO | X60: YUFI NOFERIANTO | Z60: MUHAMMAD NUR HANIF | AB60: LCD | AD60: XIAOMI | AF60: 11 T 5G | AH60: 100365 | AJ60: LCD XIAOMI MI11T/MI11T PRO | AL60: 140000 | AN60: 1 | AP60: 154000 | AR60: 154000 | AU60: =_xlfn.IFS(ISNUMBER(SEARCH("Interface", AJ60)), "Omset Interface", ISNUMBER(SEARCH("Normal", AJ60)), "Omset Normal", ISNUMBER(SEARCH("Mati Total", AJ60)), "Omset Mati Total", ISNUMBER(SEARCH("Promo", AJ60)), "Omset Promo", TRUE, "Omset lainnya") -> Omset lainnya
B61: 46238 | D61: MF-FP.0049 | F61: DO.2026.08.00043 | H61: 46238 | J61: MEMBER REGULER | L61: MR. 081297707032 | N61: EDI | P61: MUHAMMAD NUR HANIF | R61: SERVICE HP | T61: JASA | V61: MUHAMMAD IBNU SIDDIQ | X61: MUHAMMAD IBNU SIDDIQ | Z61: MUHAMMAD NUR HANIF | AB61: LCD | AD61: OPPO | AF61: a16 | AH61: 100236 | AJ61: JS HP LCD - INTERFACE | AL61: 0 | AN61: 1 | AP61: 60000 | AR61: 60000 | AU61: =_xlfn.IFS(ISNUMBER(SEARCH("Interface", AJ61)), "Omset Interface", ISNUMBER(SEARCH("Normal", AJ61)), "Omset Normal", ISNUMBER(SEARCH("Mati Total", AJ61)), "Omset Mati Total", ISNUMBER(SEARCH("Promo", AJ61)), "Omset Promo", TRUE, "Omset lainnya") -> Omset Interface
B62: 46238 | D62: MF-FP.0049 | F62: DO.2026.08.00043 | H62: 46238 | J62: MEMBER REGULER | L62: MR. 081297707032 | N62: EDI | P62: MUHAMMAD NUR HANIF | R62: SERVICE HP | T62: AKSESORIS | V62: MUHAMMAD IBNU SIDDIQ | X62: MUHAMMAD IBNU SIDDIQ | Z62: MUHAMMAD NUR HANIF | AB62: LCD | AD62: OPPO | AF62: a16 | AH62: 100194 | AJ62: LUNA USB CABLE CB-2EC | AL62: 17450 | AN62: 1 | AP62: 20000 | AR62: 20000 | AU62: =_xlfn.IFS(ISNUMBER(SEARCH("Interface", AJ62)), "Omset Interface", ISNUMBER(SEARCH("Normal", AJ62)), "Omset Normal", ISNUMBER(SEARCH("Mati Total", AJ62)), "Omset Mati Total", ISNUMBER(SEARCH("Promo", AJ62)), "Omset Promo", TRUE, "Omset lainnya") -> Omset lainnya
B63: 46238 | D63: MF-FP.0049 | F63: DO.2026.08.00043 | H63: 46238 | J63: MEMBER REGULER | L63: MR. 081297707032 | N63: EDI | P63: MUHAMMAD NUR HANIF | R63: SERVICE HP | T63: AKSESORIS | V63: MUHAMMAD IBNU SIDDIQ | X63: MUHAMMAD IBNU SIDDIQ | Z63: MUHAMMAD NUR HANIF | AB63: LCD | AD63: OPPO | AF63: a16 | AH63: 100279 | AJ63: VIVAN HYDROGEL BASIC CRYSTAL CLEAR VSP01T | AL63: 20000 | AN63: 1 | AP63: 20000 | AR63: 20000 | AU63: =_xlfn.IFS(ISNUMBER(SEARCH("Interface", AJ63)), "Omset Interface", ISNUMBER(SEARCH("Normal", AJ63)), "Omset Normal", ISNUMBER(SEARCH("Mati Total", AJ63)), "Omset Mati Total", ISNUMBER(SEARCH("Promo", AJ63)), "Omset Promo", TRUE, "Omset lainnya") -> Omset lainnya
B64: 46234 | D64: MF-FP.0012 | F64: DO.2026.07.00002 | H64: 46234 | J64: Umum | L64: MR.081584033553 | N64: PUTRI | P64: HANIF | R64: SERVICE HP | T64: JASA | V64: MUHAMMAD IBNU SIDDIQ | X64: MUHAMMAD IBNU SIDDIQ | Z64: MUHAMMAD NUR HANIF | AB64: LCD | AD64: INFINIX | AF64: NOTE 11 PRO | AH64: 100236 | AJ64: JS HP LCD - INTERFACE | AL64: 0 | AN64: 1 | AP64: 90000 | AR64: 90000 | AU64: =_xlfn.IFS(ISNUMBER(SEARCH("Interface", AJ64)), "Omset Interface", ISNUMBER(SEARCH("Normal", AJ64)), "Omset Normal", ISNUMBER(SEARCH("Mati Total", AJ64)), "Omset Mati Total", ISNUMBER(SEARCH("Promo", AJ64)), "Omset Promo", TRUE, "Omset lainnya") -> Omset Interface
B65: 46234 | D65: MF-FP.0012 | F65: DO.2026.07.00002 | H65: 46234 | J65: Umum | L65: MR.081584033553 | N65: PUTRI | P65: HANIF | R65: SERVICE HP | T65: AKSESORIS | V65: MUHAMMAD IBNU SIDDIQ | X65: MUHAMMAD IBNU SIDDIQ | Z65: MUHAMMAD NUR HANIF | AB65: LCD | AD65: INFINIX | AF65: NOTE 11 PRO | AH65: 100194 | AJ65: LUNA USB CABLE CB-2EC | AL65: 17450 | AN65: 1 | AP65: 20000 | AR65: 20000 | AU65: =_xlfn.IFS(ISNUMBER(SEARCH("Interface", AJ65)), "Omset Interface", ISNUMBER(SEARCH("Normal", AJ65)), "Omset Normal", ISNUMBER(SEARCH("Mati Total", AJ65)), "Omset Mati Total", ISNUMBER(SEARCH("Promo", AJ65)), "Omset Promo", TRUE, "Omset lainnya") -> Omset lainnya
B66: 46235 | D66: MF-FP.0014 | F66: DO.2026.08.00002 | H66: 46235 | J66: Umum | L66: MR. 087873806000 | N66: AGUS | P66: MUHAMMAD NUR HANIF | R66: SERVICE HP | T66: JASA | V66: YUFI NOFERIANTO | X66: YUFI NOFERIANTO | Z66: MUHAMMAD NUR HANIF | AB66: BATERAI | AD66: XIAOMI | AF66: X3 NFC | AH66: 100229 | AJ66: JS HP BATERAI - INTERFACE | AL66: 0 | AN66: 1 | AP66: 120000 | AR66: 120000 | AU66: =_xlfn.IFS(ISNUMBER(SEARCH("Interface", AJ66)), "Omset Interface", ISNUMBER(SEARCH("Normal", AJ66)), "Omset Normal", ISNUMBER(SEARCH("Mati Total", AJ66)), "Omset Mati Total", ISNUMBER(SEARCH("Promo", AJ66)), "Omset Promo", TRUE, "Omset lainnya") -> Omset Interface
B67: 46235 | D67: MF-FP.0014 | F67: DO.2026.08.00002 | H67: 46235 | J67: Umum | L67: MR. 087873806000 | N67: AGUS | P67: MUHAMMAD NUR HANIF | R67: SERVICE HP | T67: AKSESORIS | V67: YUFI NOFERIANTO | X67: YUFI NOFERIANTO | Z67: MUHAMMAD NUR HANIF | AB67: BATERAI | AD67: XIAOMI | AF67: X3 NFC | AH67: 100194 | AJ67: LUNA USB CABLE CB-2EC | AL67: 17450 | AN67: 1 | AP67: 20000 | AR67: 20000 | AU67: =_xlfn.IFS(ISNUMBER(SEARCH("Interface", AJ67)), "Omset Interface", ISNUMBER(SEARCH("Normal", AJ67)), "Omset Normal", ISNUMBER(SEARCH("Mati Total", AJ67)), "Omset Mati Total", ISNUMBER(SEARCH("Promo", AJ67)), "Omset Promo", TRUE, "Omset lainnya") -> Omset lainnya
B68: 46235 | D68: MF-FP.0016 | F68: DO.2026.07.00018 | H68: 46234 | J68: MEMBER REGULER | L68: MR. 081384549950 | N68: WULAN | P68: RAIHAN KAFFI BUDIMAN | R68: SERVICE HP | T68: JASA | V68: IKANG TAUFIK | X68: IKANG TAUFIK | Z68: RAIHAN KAFFI BUDIMAN | AB68: FLEXIBEL ON/OFF | AD68: SAMSUNG | AF68: A16 | AH68: 100236 | AJ68: JS HP LCD - INTERFACE | AL68: 0 | AN68: 1 | AP68: 100000 | AR68: 100000 | AU68: =_xlfn.IFS(ISNUMBER(SEARCH("Interface", AJ68)), "Omset Interface", ISNUMBER(SEARCH("Normal", AJ68)), "Omset Normal", ISNUMBER(SEARCH("Mati Total", AJ68)), "Omset Mati Total", ISNUMBER(SEARCH("Promo", AJ68)), "Omset Promo", TRUE, "Omset lainnya") -> Omset Interface
... B76: 46235 | D76: MF-FP.0018 | F76: DO.2026.08.00008 | H76: 46235 | J76: MEMBER REGULER | L76: MR. 085176719957 | N76: FAHMI | P76: RAIHAN KAFFI BUDIMAN | R76: SERVICE HP | T76: AKSESORIS | V76: FARID HASHBI SIDDIQ | X76: FARID HASHBI SIDDIQ | Z76: RAIHAN KAFFI BUDIMAN | AB76: LCD | AD76: XIAOMI | AF76: REDMI NOTE 12 | AH76: 100278 | AJ76: VIVAN HYDROGEL BASIC ANTI GLARE VSP03T | AL76: 40000 | AN76: 2 | AP76: 37500 | AR76: 75000 | AU76: =_xlfn.IFS(ISNUMBER(SEARCH("Interface", AJ76)), "Omset Interface", ISNUMBER(SEARCH("Normal", AJ76)), "Omset Normal", ISNUMBER(SEARCH("Mati Total", AJ76)), "Omset Mati Total", ISNUMBER(SEARCH("Promo", AJ76)), "Omset Promo", TRUE, "Omset lainnya") -> Omset lainnya
B77: 46234 | D77: MF-FP.0043 | F77: DO.2026.08.00013 | H77: 46234 | J77: Umum | L77: MR. 089626812542 | N77: JULIANA | P77: MUHAMMAD ANELKA | R77: PENJUALAN AKSESORIS | T77: AKSESORIS | Z77: MUHAMMAD NUR HANIF | AB77: N/A | AD77: BELUM ADA MERK | AF77: BROOKLYN TEMPERAD GLASS | AH77: 100139 | AJ77: BROOKLYN TEMPERED GLASS IPHONE 13/13 PRO/14/16E VER2 | AL77: 76000 | AN77: 1 | AP77: 126000 | AR77: 126000 | AU77: =_xlfn.IFS(ISNUMBER(SEARCH("Interface", AJ77)), "Omset Interface", ISNUMBER(SEARCH("Normal", AJ77)), "Omset Normal", ISNUMBER(SEARCH("Mati Total", AJ77)), "Omset Mati Total", ISNUMBER(SEARCH("Promo", AJ77)), "Omset Promo", TRUE, "Omset lainnya") -> Omset lainnya
B78: 46236 | D78: MF-FP.0024 | F78: DO.2026.08.00004 | H78: 46235 | J78: Umum | L78: MR. 08974300910 | N78: NISA | P78: MUHAMMAD NUR HANIF | R78: SERVICE HP | T78: AKSESORIS | V78: EGI SETYA RAMADANI | X78: EGI SETYA RAMADANI | Z78: MUHAMMAD ANELKA | AB78: REPAIR | AD78: SAMSUNG | AF78: A03 CORE | AH78: 100194 | AJ78: LUNA USB CABLE CB-2EC | AL78: 17450 | AN78: 1 | AP78: 21000 | AR78: 21000 | AU78: =_xlfn.IFS(ISNUMBER(SEARCH("Interface", AJ78)), "Omset Interface", ISNUMBER(SEARCH("Normal", AJ78)), "Omset Normal", ISNUMBER(SEARCH("Mati Total", AJ78)), "Omset Mati Total", ISNUMBER(SEARCH("Promo", AJ78)), "Omset Promo", TRUE, "Omset lainnya") -> Omset lainnya
B79: 46236 | D79: MF-FP.0024 | F79: DO.2026.08.00004 | H79: 46235 | J79: Umum | L79: MR. 08974300910 | N79: NISA | P79: MUHAMMAD NUR HANIF | R79: SERVICE HP | T79: AKSESORIS | V79: EGI SETYA RAMADANI | X79: EGI SETYA RAMADANI | Z79: MUHAMMAD ANELKA | AB79: REPAIR | AD79: SAMSUNG | AF79: A03 CORE | AH79: 100279 | AJ79: VIVAN HYDROGEL BASIC CRYSTAL CLEAR VSP01T | AL79: 20000 | AN79: 1 | AP79: 35000 | AR79: 35000 | AU79: =_xlfn.IFS(ISNUMBER(SEARCH("Interface", AJ79)), "Omset Interface", ISNUMBER(SEARCH("Normal", AJ79)), "Omset Normal", ISNUMBER(SEARCH("Mati Total", AJ79)), "Omset Mati Total", ISNUMBER(SEARCH("Promo", AJ79)), "Omset Promo", TRUE, "Omset lainnya") -> Omset lainnya
B80: 46236 | D80: MF-FP.0026 | F80: DO.2026.08.00017 | H80: 46236 | J80: Umum | L80: MR. 085794016631 | N80: ANGGI | P80: MUHAMMAD ANELKA | R80: SERVICE HP | T80: JASA | V80: FARID HASHBI SIDDIQ | X80: FARID HASHBI SIDDIQ | Z80: MUHAMMAD ANELKA | AB80: N/A | AD80: VIVO | AF80: Y12 | AH80: 100227 | AJ80: JS HP - SPAREPART BAWA - INTERFACE | AL80: 0 | AN80: 1 | AP80: 30000 | AR80: 30000 | AU80: =_xlfn.IFS(ISNUMBER(SEARCH("Interface", AJ80)), "Omset Interface", ISNUMBER(SEARCH("Normal", AJ80)), "Omset Normal", ISNUMBER(SEARCH("Mati Total", AJ80)), "Omset Mati Total", ISNUMBER(SEARCH("Promo", AJ80)), "Omset Promo", TRUE, "Omset lainnya") -> Omset Interface
B81: 46236 | D81: MF-FP.0027 | F81: DO.2026.08.00020 | H81: 46236 | J81: Umum | L81: MR. 089517384609 | N81: ALFA | P81: MUHAMMAD NUR HANIF | R81: SERVICE HP | T81: JASA | V81: YUFI NOFERIANTO | X81: YUFI NOFERIANTO | Z81: MUHAMMAD NUR HANIF | AB81: LCD | AD81: APPLE | AF81: IPHONE XR | AH81: 100236 | AJ81: JS HP LCD - INTERFACE | AL81: 0 | AN81: 1 | AP81: 115000 | AR81: 115000 | AU81: =_xlfn.IFS(ISNUMBER(SEARCH("Interface", AJ81)), "Omset Interface", ISNUMBER(SEARCH("Normal", AJ81)), "Omset Normal", ISNUMBER(SEARCH("Mati Total", AJ81)), "Omset Mati Total", ISNUMBER(SEARCH("Promo", AJ81)), "Omset Promo", TRUE, "Omset lainnya") -> Omset Interface
B82: 46236 | D82: MF-FP.0027 | F82: DO.2026.08.00020 | H82: 46236 | J82: Umum | L82: MR. 089517384609 | N82: ALFA | P82: MUHAMMAD NUR HANIF | R82: SERVICE HP | T82: AKSESORIS | V82: YUFI NOFERIANTO | X82: YUFI NOFERIANTO | Z82: MUHAMMAD NUR HANIF | AB82: LCD | AD82: APPLE | AF82: IPHONE XR | AH82: 100195 | AJ82: LUNA USB CABLE CB-2EL | AL82: 19300 | AN82: 1 | AP82: 20000 | AR82: 20000 | AU82: =_xlfn.IFS(ISNUMBER(SEARCH("Interface", AJ82)), "Omset Interface", ISNUMBER(SEARCH("Normal", AJ82)), "Omset Normal", ISNUMBER(SEARCH("Mati Total", AJ82)), "Omset Mati Total", ISNUMBER(SEARCH("Promo", AJ82)), "Omset Promo", TRUE, "Omset lainnya") -> Omset lainnya
B83: 46236 | D83: MF-FP.0029 | F83: DO.2026.08.00022 | H83: 46236 | J83: Umum | L83: MR. 081317591905 | N83: DAFI | P83: MUHAMMAD NUR HANIF | R83: SERVICE HP | T83: JASA | V83: MUHAMMAD IBNU SIDDIQ | X83: MUHAMMAD IBNU SIDDIQ | Z83: MUHAMMAD NUR HANIF | AB83: LCD | AD83: XIAOMI | AF83: POCO X3 | AH83: 100236 | AJ83: JS HP LCD - INTERFACE | AL83: 0 | AN83: 1 | AP83: 75000 | AR83: 75000 | AU83: =_xlfn.IFS(ISNUMBER(SEARCH("Interface", AJ83)), "Omset Interface", ISNUMBER(SEARCH("Normal", AJ83)), "Omset Normal", ISNUMBER(SEARCH("Mati Total", AJ83)), "Omset Mati Total", ISNUMBER(SEARCH("Promo", AJ83)), "Omset Promo", TRUE, "Omset lainnya") -> Omset Interface
B84: 46236 | D84: MF-FP.0029 | F84: DO.2026.08.00022 | H84: 46236 | J84: Umum | L84: MR. 081317591905 | N84: DAFI | P84: MUHAMMAD NUR HANIF | R84: SERVICE HP | T84: AKSESORIS | V84: MUHAMMAD IBNU SIDDIQ | X84: MUHAMMAD IBNU SIDDIQ | Z84: MUHAMMAD NUR HANIF | AB84: LCD | AD84: XIAOMI | AF84: POCO X3 | AH84: 100279 | AJ84: VIVAN HYDROGEL BASIC CRYSTAL CLEAR VSP01T | AL84: 20000 | AN84: 1 | AP84: 38000 | AR84: 38000 | AU84: =_xlfn.IFS(ISNUMBER(SEARCH("Interface", AJ84)), "Omset Interface", ISNUMBER(SEARCH("Normal", AJ84)), "Omset Normal", ISNUMBER(SEARCH("Mati Total", AJ84)), "Omset Mati Total", ISNUMBER(SEARCH("Promo", AJ84)), "Omset Promo", TRUE, "Omset lainnya") -> Omset lainnya
...

Sheet Pivot
A1: KATEGORI BARANG | B1: JASA
A3: Sum of TOTAL HARGA | B3: Column Labels
A4: Row Labels | B4: Omset Interface | C4: Omset lainnya | D4: Omset Mati Total | E4: Omset Normal | F4: Grand Total
A5: IKANG TAUFIK | B5: 4940500 | D5: 1970000 | E5: 3565000 | F5: 10475500
A6: YUFI NOFERIANTO | B6: 4529900 | C6: 24000 | D6: 400000 | E6: 3453500 | F6: 8407400
A7: MUHAMMAD IBNU SIDDIQ | B7: 3275000 | C7: 200000 | D7: 510000 | E7: 2113000 | F7: 6098000
A8: FARID HASHBI SIDDIQ | B8: 2972000 | E8: 456000 | F8: 3428000
A9: EGI SETYA RAMADANI | B9: 1701500 | C9: 50000 | E9: 340000 | F9: 2091500
A10: Grand Total | B10: 17418900 | C10: 274000 | D10: 2880000 | E10: 9927500 | F10: 30500400

Sheet RAW
A1: Bagi Hasil Teknisi — Cabang CIBUBUR
A2: Periode: 24 Juli 2026 – 23 Agustus 2026 · Tarif: Interface 20%, Normal 30%, Mati Total 32%, Promo 60%, Lainnya 30%, pembanding flat 30%
A4: Nama Teknisi | B4: Cabang | C4: Baris | D4: Omzet Interface | E4: Omzet Normal | F4: Omzet Mati Total | G4: Omzet Promo | H4: Omzet Lainnya | I4: Omzet Jasa (Total) | J4: Bagi Hasil Interface | K4: Bagi Hasil Normal | L4: Bagi Hasil Mati Total | M4: Bagi Hasil Promo | N4: Bagi Hasil Lainnya | O4: Bagi Hasil (Aturan) | P4: Pembanding 30% | Q4: Selisih | R4: Efektif % | S4: Potongan Refund | T4: Potongan AR | U4: Potongan Kasbon | V4: Keterlambatan | W4: Potongan Minus Audit | X4: Potongan Audit Compliance | Y4: Biaya Pendaftaran Koperasi | Z4: Simpanan Pokok | AA4: Simpanan Wajib | AB4: Total Potongan | AC4: Gaji Teknisi | AD4: Nett Bagi hasil | AE4: Cadangan 7 Tahun / bulan | AF4: Cadangan 7 Tahun | AG4: Total Cadangan 7 Tahun
A5: IKANG TAUFIK | B5: CIBUBUR | C5: 38 | D5: 4940500 | E5: 3565000 | F5: 1970000 | G5: 0 | I5: =SUM(D5:H5) -> 10475500 | J5: =D5*0.2 -> 988100 | K5: =E5*0.3 -> 1069500 | L5: =F5*0.32 -> 630400 | M5: =G5*0.6 -> 0 | N5: =H5*0.3 -> 0 | O5: =SUM(J5:N5) -> 2688000 | P5: =I5*0.3 -> 3142650 | Q5: =O5-P5 -> -454650 | R5: =IF(I5=0,0,O5/I5*100) -> 25.659873 | S5: 0 | T5: 0 | U5: 0 | V5: 0 | W5: 0 | X5: 0 | Y5: 0 | Z5: 0 | AA5: 100000 | AB5: =SUM(S5:AA5) -> 100000 | AC5: 2312000 | AD5: =O5-AB5+AC5 -> 4900000 | AG5: =AE5+AF5 -> 0
A6: YUFI NOFERIANTO | B6: CIBUBUR | C6: 42 | D6: 4529900 | E6: 3453500 | F6: 400000 | G6: 0 | H6: 24000 | I6: =SUM(D6:H6) -> 8407400 | J6: =D6*0.2 -> 905980 | K6: =E6*0.3 -> 1036050 | L6: =F6*0.32 -> 128000 | M6: =G6*0.6 -> 0 | N6: =H6*0.3 -> 7200 | O6: =SUM(J6:N6) -> 2077230 | P6: =I6*0.3 -> 2522220 | Q6: =O6-P6 -> -444990 | R6: =IF(I6=0,0,O6/I6*100) -> 24.707163 | S6: 0 | T6: 0 | U6: 0 | V6: 0 | W6: 0 | X6: 0 | Y6: 0 | Z6: 0 | AA6: 0 | AB6: =SUM(S6:AA6) -> 0 | AD6: =O6-AB6+AC6 -> 2077230 | AG6: =AE6+AF6 -> 0
A7: MUHAMMAD IBNU SIDDIQ | B7: CIBUBUR | C7: 53 | D7: 3275000 | E7: 2113000 | F7: 510000 | G7: 0 | H7: 200000 | I7: =SUM(D7:H7) -> 6098000 | J7: =D7*0.2 -> 655000 | K7: =E7*0.3 -> 633900 | L7: =F7*0.32 -> 163200 | M7: =G7*0.6 -> 0 | N7: =H7*0.3 -> 60000 | O7: =SUM(J7:N7) -> 1512100 | P7: =I7*0.3 -> 1829400 | Q7: =O7-P7 -> -317300 | R7: =IF(I7=0,0,O7/I7*100) -> 24.796655 | S7: 0 | T7: 0 | U7: 0 | V7: 0 | W7: 0 | X7: 0 | Y7: 0 | Z7: 0 | AA7: 0 | AB7: =SUM(S7:AA7) -> 0 | AD7: =O7-AB7+AC7 -> 1512100 | AG7: =AE7+AF7 -> 0
A8: FARID HASHBI SIDDIQ | B8: CIBUBUR | C8: 37 | D8: 2972000 | E8: 456000 | G8: 0 | I8: =SUM(D8:H8) -> 3428000 | J8: =D8*0.2 -> 594400 | K8: =E8*0.3 -> 136800 | L8: =F8*0.32 -> 0 | M8: =G8*0.6 -> 0 | N8: =H8*0.3 -> 0 | O8: =SUM(J8:N8) -> 731200 | P8: =I8*0.3 -> 1028400 | Q8: =O8-P8 -> -297200 | R8: =IF(I8=0,0,O8/I8*100) -> 21.330222 | S8: 0 | T8: 0 | U8: 0 | V8: 0 | W8: 0 | X8: 0 | Y8: 0 | Z8: 0 | AA8: 0 | AB8: =SUM(S8:AA8) -> 0 | AC8: 538031 | AD8: =O8-AB8+AC8 -> 1269231 | AG8: =AE8+AF8 -> 0
A9: EGI SETYA RAMADANI | B9: CIBUBUR | C9: 17 | D9: 1701500 | E9: 340000 | G9: 0 | H9: 50000 | I9: =SUM(D9:H9) -> 2091500 | J9: =D9*0.2 -> 340300 | K9: =E9*0.3 -> 102000 | L9: =F9*0.32 -> 0 | M9: =G9*0.6 -> 0 | N9: =H9*0.3 -> 15000 | O9: =SUM(J9:N9) -> 457300 | P9: =I9*0.3 -> 627450 | Q9: =O9-P9 -> -170150 | R9: =IF(I9=0,0,O9/I9*100) -> 21.86469 | S9: 0 | T9: 0 | U9: 0 | V9: 0 | W9: 0 | X9: 0 | Y9: 0 | Z9: 0 | AA9: 0 | AB9: =SUM(S9:AA9) -> 0 | AC9: 426138 | AD9: =O9-AB9+AC9 -> 883438 | AG9: =AE9+AF9 -> 0
A10: TOTAL | C10: =SUM(C5:C9) -> 187 | D10: =SUM(D5:D9) -> 17418900 | E10: =SUM(E5:E9) -> 9927500 | F10: =SUM(F5:F9) -> 2880000 | G10: =SUM(G5:G9) -> 0 | H10: =SUM(H5:H9) -> 274000 | I10: =SUM(I5:I9) -> 30500400 | J10: =SUM(J5:J9) -> 3483780 | ... Q10: =SUM(Q5:Q9) -> -1684290 | R10: =IF(I10=0,0,O10/I10*100) -> 24.47781 | S10: =SUM(S5:S9) -> 0 | T10: =SUM(T5:T9) -> 0 | U10: =SUM(U5:U9) -> 0 | V10: =SUM(V5:V9) -> 0 | W10: =SUM(W5:W9) -> 0 | X10: =SUM(X5:X9) -> 0 | Y10: =SUM(Y5:Y9) -> 0 | Z10: =SUM(Z5:Z9) -> 0 | ... AG10: =SUM(AG5:AG9) -> 0

Sheet final
B2: DAFTAR BAGI HASIL MFLASH CIBUBUR PT MADINAH MULTIMEDIA TELEKOMUNIKASI
B3: TEKNISI HANDPHONE & LAPTOP
B4: PERIODE: | D4: AGUSTUS 2026
B7: NO | C7: NIK | D7: NAMA | E7: JABATAN | F7: LOKASI KERJA | G7: Bank | H7: No. Rek. | I7: A/n | J7: DATA REKENING | K7: STATUS KARYAWAN | L7: TOTAL LABA KOTOR JASA SERVICE HP | M7: PENERIMAAN BAGI HASIL | N7: PENDAPATAN LAIN-LAIN | O7: TOTAL PENDAPATAN | P7: Potongan Refund | Q7: Potongan AR | R7: Potongan Kasbon | S7: Keterlambatan | T7: Potongan Minus Audit | U7: Potongan Audit Compliance | V7: Biaya Pendaftaran Koperasi | W7: Simpanan Pokok | X7: Simpanan Wajib | Y7: Total Potongan | Z7: BAGI HASIL NETT | AA7: INFORMASI
B8: 1 | D8: =RAW!A5 -> IKANG TAUFIK | E8: Teknisi | F8: =RAW!B5 -> CIBUBUR | G8: BSI | H8: 7368152751 | J8: =CONCATENATE($G$7,G8,$H$7,H8,$I$7,I8) -> Bank BSI No. Rek. 7368152751 A/n | K8: MITRA | L8: =RAW!I5 -> 10475500 | M8: =RAW!O5 -> 2688000 | N8: =RAW!AC5 -> 2312000 | O8: =SUM(M8:N8) -> 5000000 | P8: =RAW!S5 -> 0 | Q8: =RAW!T5 -> 0 | R8: =RAW!U5 -> 0 | S8: =RAW!V5 -> 0 | T8: =RAW!W5 -> 0 | U8: =RAW!X5 -> 0 | V8: =RAW!Y5 -> 0 | W8: =RAW!Z5 -> 0 | ... Y8: =RAW!AB5 -> 100000 | Z8: =O8-Y8 -> 4900000 | AA8: =_xlfn.TEXTJOIN(" | ",TRUE,IF(V8>0,"Biaya Pendaftaran Koperasi: "&TEXT(V8,"#.##0"),""),IF(W8>0,"Simpanan Pokok: "&TEXT(W8,"#.##0"),""),IF(X8>0,"Simpanan Wajib: "&TEXT(X8,"#.##0"),"")) -> Simpanan Wajib: 100.000
B9: 2 | D9: =RAW!A6 -> YUFI NOFERIANTO | E9: Teknisi | F9: =RAW!B6 -> CIBUBUR | G9: BSI | H9: 7330237591 | I9: YUVI NOFERIANTO | J9: Bank BSI No. Rek. 7330237591 A/n YUVI NOFERIANTO | K9: MITRA | L9: =RAW!I6 -> 8407400 | M9: =RAW!O6 -> 2077230 | N9: =RAW!AC6 -> 0 | O9: =SUM(M9:N9) -> 2077230 | P9: =RAW!S6 -> 0 | Q9: =RAW!T6 -> 0 | R9: =RAW!U6 -> 0 | S9: =RAW!V6 -> 0 | T9: =RAW!W6 -> 0 | U9: =RAW!X6 -> 0 | V9: =RAW!Y6 -> 0 | W9: =RAW!Z6 -> 0 | ... Y9: =RAW!AB6 -> 0 | Z9: =O9-Y9 -> 2077230 | AA9: =_xlfn.TEXTJOIN(" | ",TRUE,IF(V9>0,"Biaya Pendaftaran Koperasi: "&TEXT(V9,"#.##0"),""),IF(W9>0,"Simpanan Pokok: "&TEXT(W9,"#.##0"),""),IF(X9>0,"Simpanan Wajib: "&TEXT(X9,"#.##0"),""))
B10: 3 | D10: =RAW!A7 -> MUHAMMAD IBNU SIDDIQ | E10: Teknisi | F10: =RAW!B7 -> CIBUBUR | G10: BSI | H10: 7340549378 | I10: MUHAMMAD IBNU SIDDIQ | J10: Bank BSI No. Rek. 7340549378 A/n MUHAMMAD IBNU SIDDIQ | K10: MITRA | L10: =RAW!I7 -> 6098000 | M10: =RAW!O7 -> 1512100 | N10: =RAW!AC7 -> 0 | O10: =SUM(M10:N10) -> 1512100 | P10: =RAW!S7 -> 0 | Q10: =RAW!T7 -> 0 | R10: =RAW!U7 -> 0 | S10: =RAW!V7 -> 0 | T10: =RAW!W7 -> 0 | U10: =RAW!X7 -> 0 | V10: =RAW!Y7 -> 0 | W10: =RAW!Z7 -> 0 | ... Y10: =RAW!AB7 -> 0 | Z10: =O10-Y10 -> 1512100 | AA10: =_xlfn.TEXTJOIN(" | ",TRUE,IF(V10>0,"Biaya Pendaftaran Koperasi: "&TEXT(V10,"#.##0"),""),IF(W10>0,"Simpanan Pokok: "&TEXT(W10,"#.##0"),""),IF(X10>0,"Simpanan Wajib: "&TEXT(X10,"#.##0"),""))
B11: 4 | D11: =RAW!A8 -> FARID HASHBI SIDDIQ | E11: Teknisi | F11: =RAW!B8 -> CIBUBUR | G11: BSI | J11: =CONCATENATE($G$7,G11,$H$7,H11,$I$7,I11) -> Bank BSI No. Rek. A/n | K11: MITRA | L11: =RAW!I8 -> 3428000 | M11: =RAW!O8 -> 731200 | N11: =RAW!AC8 -> 538031 | O11: =SUM(M11:N11) -> 1269231 | P11: =RAW!S8 -> 0 | Q11: =RAW!T8 -> 0 | R11: =RAW!U8 -> 0 | S11: =RAW!V8 -> 0 | T11: =RAW!W8 -> 0 | U11: =RAW!X8 -> 0 | V11: =RAW!Y8 -> 0 | W11: =RAW!Z8 -> 0 | ... Y11: =RAW!AB8 -> 0 | Z11: =O11-Y11 -> 1269231 | AA11: =_xlfn.TEXTJOIN(" | ",TRUE,IF(V11>0,"Biaya Pendaftaran Koperasi: "&TEXT(V11,"#.##0"),""),IF(W11>0,"Simpanan Pokok: "&TEXT(W11,"#.##0"),""),IF(X11>0,"Simpanan Wajib: "&TEXT(X11,"#.##0"),""))
B12: 5 | D12: =RAW!A9 -> EGI SETYA RAMADANI | E12: Teknisi | F12: =RAW!B9 -> CIBUBUR | G12: BSI | H12: 7355932456 | I12: Egi Setya Ramadhani | J12: Bank BSI No. Rek. 7355932456 A/n Egi Setya Ramadhani | K12: MITRA | L12: =RAW!I9 -> 2091500 | M12: =RAW!O9 -> 457300 | N12: =RAW!AC9 -> 426138 | O12: =SUM(M12:N12) -> 883438 | P12: =RAW!S9 -> 0 | Q12: =RAW!T9 -> 0 | R12: =RAW!U9 -> 0 | S12: =RAW!V9 -> 0 | T12: =RAW!W9 -> 0 | U12: =RAW!X9 -> 0 | V12: =RAW!Y9 -> 0 | W12: =RAW!Z9 -> 0 | ... Y12: =RAW!AB9 -> 0 | Z12: =O12-Y12 -> 883438 | AA12: =_xlfn.TEXTJOIN(" | ",TRUE,IF(V12>0,"Biaya Pendaftaran Koperasi: "&TEXT(V12,"#.##0"),""),IF(W12>0,"Simpanan Pokok: "&TEXT(W12,"#.##0"),""),IF(X12>0,"Simpanan Wajib: "&TEXT(X12,"#.##0"),""))
B13: TOTAL | L13: =SUM(L8:L12) -> 30500400 | M13: =SUM(M8:M12) -> 7465830 | N13: =SUM(N8:N12) -> 3276169 | O13: =SUM(O8:O12) -> 10741999 | P13: =SUM(P8:P12) -> 0 | Q13: =SUM(Q8:Q12) -> 0 | R13: =SUM(R8:R12) -> 0 | S13: =SUM(S8:S12) -> 0 | ... Z13: =SUM(Z8:Z12) -> 10641999
O16: Jakarta, | P16: =TODAY() -> 46265
D17: Approved by | O17: Prepared by | S17: Prepared by | Y17: Prepared by
D24: Deni Darmawan | O24: Muhamad Yudisya Andita | S24: Galih Permana | Y24: Zaskanul Tibalky
D25: Owner Madinah Group | O25: Corcomm | S25: Finance & Acc Manager | Y25: HR Manager
